Failed to clear Elasticsearch index: ConnectionError((<urllib3.connection.HTTPConnection object at 0x0000020F1B4C7550>, 'Connection to 192.168.19.128 timed out. (connect timeout=10)')) caused by: ConnectTimeoutError((<urllib3.connection.HTTPConnection object at 0x0000020F1B4C7550>, 'Connection to 192.168.19.128 timed out. (connect timeout=10)'))
Traceback (most recent call last):
  File "C:\zhizhi_mall\.venv\Lib\site-packages\urllib3\connection.py", line 174, in _new_conn
    conn = connection.create_connection(
           ^^^^^^^^^^^^^^^^^^^^^^^^^^^^^
  File "C:\zhizhi_mall\.venv\Lib\site-packages\urllib3\util\connection.py", line 95, in create_connection
    raise err
  File "C:\zhizhi_mall\.venv\Lib\site-packages\urllib3\util\connection.py", line 85, in create_connection
    sock.connect(sa)
TimeoutError: timed out

During handling of the above exception, another exception occurred:

Traceback (most recent call last):
  File "C:\zhizhi_mall\.venv\Lib\site-packages\elasticsearch\connection\http_urllib3.py", line 95, in perform_request
    response = self.pool.urlopen(method, url, body, retries=False, headers=self.headers, **kw)
               ^^^^^^^^^^^^^^^^^^^^^^^^^^^^^^^^^^^^^^^^^^^^^^^^^^^^^^^^^^^^^^^^^^^^^^^^^^^^^^^
  File "C:\zhizhi_mall\.venv\Lib\site-packages\urllib3\connectionpool.py", line 799, in urlopen
    retries = retries.increment(
              ^^^^^^^^^^^^^^^^^^
  File "C:\zhizhi_mall\.venv\Lib\site-packages\urllib3\util\retry.py", line 525, in increment
    raise six.reraise(type(error), error, _stacktrace)
          ^^^^^^^^^^^^^^^^^^^^^^^^^^^^^^^^^^^^^^^^^^^^
  File "C:\zhizhi_mall\.venv\Lib\site-packages\urllib3\packages\six.py", line 770, in reraise
    raise value
  File "C:\zhizhi_mall\.venv\Lib\site-packages\urllib3\connectionpool.py", line 715, in urlopen
    httplib_response = self._make_request(
                       ^^^^^^^^^^^^^^^^^^^
  File "C:\zhizhi_mall\.venv\Lib\site-packages\urllib3\connectionpool.py", line 416, in _make_request
    conn.request(method, url, **httplib_request_kw)
  File "C:\zhizhi_mall\.venv\Lib\site-packages\urllib3\connection.py", line 244, in request
    super(HTTPConnection, self).request(method, url, body=body, headers=headers)
  File "c:\Users\֦֦\AppData\Local\Programs\Python\Python311\Lib\http\client.py", line 1298, in request
    self._send_request(method, url, body, headers, encode_chunked)
  File "c:\Users\֦֦\AppData\Local\Programs\Python\Python311\Lib\http\client.py", line 1344, in _send_request
    self.endheaders(body, encode_chunked=encode_chunked)
  File "c:\Users\֦֦\AppData\Local\Programs\Python\Python311\Lib\http\client.py", line 1293, in endheaders
    self._send_output(message_body, encode_chunked=encode_chunked)
  File "c:\Users\֦֦\AppData\Local\Programs\Python\Python311\Lib\http\client.py", line 1052, in _send_output
    self.send(msg)
  File "c:\Users\֦֦\AppData\Local\Programs\Python\Python311\Lib\http\client.py", line 990, in send
    self.connect()
  File "C:\zhizhi_mall\.venv\Lib\site-packages\urllib3\connection.py", line 205, in connect
    conn = self._new_conn()
           ^^^^^^^^^^^^^^^^
  File "C:\zhizhi_mall\.venv\Lib\site-packages\urllib3\connection.py", line 179, in _new_conn
    raise ConnectTimeoutError(
urllib3.exceptions.ConnectTimeoutError: (<urllib3.connection.HTTPConnection object at 0x0000020F1B4C7550>, 'Connection to 192.168.19.128 timed out. (connect timeout=10)')

During handling of the above exception, another exception occurred:

Traceback (most recent call last):
  File "C:\zhizhi_mall\.venv\Lib\site-packages\haystack\backends\elasticsearch_backend.py", line 299, in clear
    self.conn.indices.delete(index=self.index_name, ignore=404)
  File "C:\zhizhi_mall\.venv\Lib\site-packages\elasticsearch\client\utils.py", line 69, in _wrapped
    return func(*args, params=params, **kwargs)
           ^^^^^^^^^^^^^^^^^^^^^^^^^^^^^^^^^^^^
  File "C:\zhizhi_mall\.venv\Lib\site-packages\elasticsearch\client\indices.py", line 200, in delete
    return self.transport.perform_request('DELETE', _make_path(index),
           ^^^^^^^^^^^^^^^^^^^^^^^^^^^^^^^^^^^^^^^^^^^^^^^^^^^^^^^^^^^
  File "C:\zhizhi_mall\.venv\Lib\site-packages\elasticsearch\transport.py", line 327, in perform_request
    status, headers, data = connection.perform_request(method, url, params, body, ignore=ignore, timeout=timeout)
                            ^^^^^^^^^^^^^^^^^^^^^^^^^^^^^^^^^^^^^^^^^^^^^^^^^^^^^^^^^^^^^^^^^^^^^^^^^^^^^^^^^^^^^
  File "C:\zhizhi_mall\.venv\Lib\site-packages\elasticsearch\connection\http_urllib3.py", line 106, in perform_request
    raise ConnectionError('N/A', str(e), e)
elasticsearch.exceptions.ConnectionError: ConnectionError((<urllib3.connection.HTTPConnection object at 0x0000020F1B4C7550>, 'Connection to 192.168.19.128 timed out. (connect timeout=10)')) caused by: ConnectTimeoutError((<urllib3.connection.HTTPConnection object at 0x0000020F1B4C7550>, 'Connection to 192.168.19.128 timed out. (connect timeout=10)'))
